<?xml version="1.0" encoding="UTF-8"?>
<!-- Generated by org.testng.reporters.JUnitXMLReporter -->
<testsuite hostname="Pranab" name="Test" tests="42" failures="6" timestamp="12 Apr 2019 20:49:25 GMT" time="12.37" errors="0">
  <testcase name="@AfterMethod m4" time="0.0" classname="default1.Screenshot_Of_Failed_Test_Cases">
    <failure type="java.lang.NullPointerException">
      <![CDATA[java.lang.NullPointerException
	at default1.Screenshot_Of_Failed_Test_Cases.take_Screenshot(Screenshot_Of_Failed_Test_Cases.java:44)
	at default1.Screenshot_Of_Failed_Test_Cases.m4(Screenshot_Of_Failed_Test_Cases.java:61)
	at java.util.concurrent.FutureTask.run(Unknown Source)
	at java.util.concurrent.ThreadPoolExecutor.runWorker(Unknown Source)
	at java.util.concurrent.ThreadPoolExecutor$Worker.run(Unknown Source)
	at java.lang.Thread.run(Unknown Source)
... Removed 18 stack frames]]>
    </failure>
  </testcase> <!-- @AfterMethod m4 -->
  <testcase name="m1" time="0.012" classname="com.code.trial.Array_To_Array_List"/>
  <testcase name="comparator" time="0.002" classname="comparable_Vs_Comparator.Comparator_Test"/>
  <testcase name="remainder" time="0.001" classname="math.FooBoo"/>
  <testcase name="arraySorting2" time="0.002" classname="default3.Array1"/>
  <testcase name="m2" time="0.002" classname="Default2.Sort_Array"/>
  <testcase name="test" time="0.001" classname="default3.Serialization_DeSerialization">
    <failure type="java.io.FileNotFoundException" message="C:\Users\Pranab Pc\Desktop\file.ser (The system cannot find the path specified)">
      <![CDATA[java.io.FileNotFoundException: C:\Users\Pranab Pc\Desktop\file.ser (The system cannot find the path specified)
	at java.io.FileInputStream.open0(Native Method)
	at java.io.FileInputStream.open(Unknown Source)
	at java.io.FileInputStream.<init>(Unknown Source)
	at java.io.FileInputStream.<init>(Unknown Source)
	at default3.Serialization_DeSerialization.deSerialized(Serialization_DeSerialization.java:43)
	at default3.Serialization_DeSerialization.test(Serialization_DeSerialization.java:19)
	at java.util.concurrent.FutureTask.run(Unknown Source)
	at java.util.concurrent.ThreadPoolExecutor.runWorker(Unknown Source)
	at java.util.concurrent.ThreadPoolExecutor$Worker.run(Unknown Source)
	at java.lang.Thread.run(Unknown Source)
... Removed 16 stack frames]]>
    </failure>
  </testcase> <!-- test -->
  <testcase name="m3" time="0.001" classname="default3.Map_Java"/>
  <testcase name="m2" time="0.003" classname="Default2.Count_Duplicate"/>
  <testcase name="m3" time="0.001" classname="default3.Set_Java"/>
  <testcase name="Prime_Number" time="0.001" classname="math.PrimeNumber"/>
  <testcase name="m1" time="0.003" classname="super_Method.ClassTest"/>
  <testcase name="m4" time="0.001" classname="com.code.trial.Prime_Number"/>
  <testcase name="m1" time="12.08" classname="default1.Test1">
    <failure type="java.lang.AssertionError" message="expected [15] but found [4]">
      <![CDATA[java.lang.AssertionError: expected [15] but found [4]
	at default1.Test1.m1(Test1.java:30)
	at java.util.concurrent.FutureTask.run(Unknown Source)
	at java.util.concurrent.ThreadPoolExecutor.runWorker(Unknown Source)
	at java.util.concurrent.ThreadPoolExecutor$Worker.run(Unknown Source)
	at java.lang.Thread.run(Unknown Source)
... Removed 22 stack frames]]>
    </failure>
  </testcase> <!-- m1 -->
  <testcase name="m6" time="0.006" classname="default1.Test2"/>
  <testcase name="m7" time="0.001" classname="default1.Test2">
    <failure type="java.lang.AssertionError" message="expected [7] but found [5]">
      <![CDATA[java.lang.AssertionError: expected [7] but found [5]
	at default1.Test2.m7(Test2.java:21)
	at java.util.concurrent.FutureTask.run(Unknown Source)
	at java.util.concurrent.ThreadPoolExecutor.runWorker(Unknown Source)
	at java.util.concurrent.ThreadPoolExecutor$Worker.run(Unknown Source)
	at java.lang.Thread.run(Unknown Source)
... Removed 22 stack frames]]>
    </failure>
  </testcase> <!-- m7 -->
  <testcase name="m1" time="0.001" classname="com.code.trial.B"/>
  <testcase name="m7" time="0.001" classname="default3.Collection_Framework_1"/>
  <testcase name="m1" time="0.133" classname="default1.Screenshot_Of_Failed_Test_Cases">
    <failure type="java.lang.IllegalStateException" message="The driver executable does not exist: C:\Users\Pranab Pc\Desktop\Drivers\geckodriver.exe">
      <![CDATA[java.lang.IllegalStateException: The driver executable does not exist: C:\Users\Pranab Pc\Desktop\Drivers\geckodriver.exe
	at com.google.common.base.Preconditions.checkState(Preconditions.java:585)
	at org.openqa.selenium.remote.service.DriverService.checkExecutable(DriverService.java:146)
	at org.openqa.selenium.remote.service.DriverService.findExecutable(DriverService.java:141)
	at org.openqa.selenium.firefox.GeckoDriverService.access$100(GeckoDriverService.java:44)
	at org.openqa.selenium.firefox.GeckoDriverService$Builder.findDefaultExecutable(GeckoDriverService.java:167)
	at org.openqa.selenium.remote.service.DriverService$Builder.build(DriverService.java:355)
	at org.openqa.selenium.firefox.FirefoxDriver.toExecutor(FirefoxDriver.java:190)
	at org.openqa.selenium.firefox.FirefoxDriver.<init>(FirefoxDriver.java:147)
	at org.openqa.selenium.firefox.FirefoxDriver.<init>(FirefoxDriver.java:125)
	at default1.Screenshot_Of_Failed_Test_Cases.m1(Screenshot_Of_Failed_Test_Cases.java:30)
	at java.util.concurrent.FutureTask.run(Unknown Source)
	at java.util.concurrent.ThreadPoolExecutor.runWorker(Unknown Source)
	at java.util.concurrent.ThreadPoolExecutor$Worker.run(Unknown Source)
	at java.lang.Thread.run(Unknown Source)
... Removed 16 stack frames]]>
    </failure>
  </testcase> <!-- m1 -->
  <testcase name="m2" time="0.001" classname="com.code.trial.A"/>
  <testcase name="m3" time="0.001" classname="com.code.trial.A"/>
  <testcase name="m4" time="0.002" classname="com.code.trial.A"/>
  <testcase name="m7" time="0.001" classname="com.code.trial.A"/>
  <testcase name="fibonacci" time="0.001" classname="math.Fabonachi_Number"/>
  <testcase name="m1" time="0.001" classname="default3.Singleton_ABC"/>
  <testcase name="m1" time="0.001" classname="default3.Fibonaccci_Number"/>
  <testcase name="m2" time="0.001" classname="Default2.A"/>
  <testcase name="m1" time="0.001" classname="Default2.ReTestFailed_Test_cases">
    <skipped/>
  </testcase> <!-- m1 -->
  <testcase name="m1" time="0.0" classname="Default2.ReTestFailed_Test_cases">
    <skipped/>
  </testcase> <!-- m1 -->
  <testcase name="m1" time="0.001" classname="Default2.ReTestFailed_Test_cases">
    <skipped/>
  </testcase> <!-- m1 -->
  <testcase name="m1" time="0.001" classname="Default2.ReTestFailed_Test_cases">
    <skipped/>
  </testcase> <!-- m1 -->
  <testcase name="m1" time="0.002" classname="Default2.ReTestFailed_Test_cases">
    <failure type="java.lang.AssertionError" message="expected [8] but found [5]">
      <![CDATA[java.lang.AssertionError: expected [8] but found [5]
	at Default2.ReTestFailed_Test_cases.m1(ReTestFailed_Test_cases.java:10)
	at java.util.concurrent.FutureTask.run(Unknown Source)
	at java.util.concurrent.ThreadPoolExecutor.runWorker(Unknown Source)
	at java.util.concurrent.ThreadPoolExecutor$Worker.run(Unknown Source)
	at java.lang.Thread.run(Unknown Source)
... Removed 22 stack frames]]>
    </failure>
  </testcase> <!-- m1 -->
  <testcase name="m2" time="0.001" classname="Default2.ReTestFailed_Test_cases">
    <skipped/>
  </testcase> <!-- m2 -->
  <testcase name="m2" time="0.0" classname="Default2.ReTestFailed_Test_cases">
    <skipped/>
  </testcase> <!-- m2 -->
  <testcase name="m2" time="0.0" classname="Default2.ReTestFailed_Test_cases">
    <skipped/>
  </testcase> <!-- m2 -->
  <testcase name="m2" time="0.001" classname="Default2.ReTestFailed_Test_cases">
    <skipped/>
  </testcase> <!-- m2 -->
  <testcase name="m2" time="0.0" classname="Default2.ReTestFailed_Test_cases">
    <failure type="java.lang.AssertionError" message="expected [7] but found [5]">
      <![CDATA[java.lang.AssertionError: expected [7] but found [5]
	at Default2.ReTestFailed_Test_cases.m2(ReTestFailed_Test_cases.java:16)
	at java.util.concurrent.FutureTask.run(Unknown Source)
	at java.util.concurrent.ThreadPoolExecutor.runWorker(Unknown Source)
	at java.util.concurrent.ThreadPoolExecutor$Worker.run(Unknown Source)
	at java.lang.Thread.run(Unknown Source)
... Removed 22 stack frames]]>
    </failure>
  </testcase> <!-- m2 -->
  <testcase name="m1" time="0.001" classname="math.i_Plus_Plus"/>
  <testcase name="m2" time="0.001" classname="math.i_Plus_Plus"/>
  <testcase name="m1" time="0.001" classname="Default2.Prime_Number"/>
  <testcase name="m2" time="0.001" classname="default3.Duplicate_In_String"/>
  <testcase name="m3" time="0.001" classname="Default2.Binary_Search"/>
  <testcase name="comparator" time="0.003" classname="default3.Comparable_Vs_Comparator"/>
</testsuite> <!-- Test -->
