<?xml version="1.0" encoding="UTF-8"?>
<testng-results skipped="0" failed="1" total="1" passed="0">
  <reporter-output>
  </reporter-output>
  <suite name="Default suite" duration-ms="12092" started-at="2019-03-23T18:18:48Z" finished-at="2019-03-23T18:19:00Z">
    <groups>
    </groups>
    <test name="Default test" duration-ms="12092" started-at="2019-03-23T18:18:48Z" finished-at="2019-03-23T18:19:00Z">
      <class name="default1.Screenshot_Of_Failed_Test_Cases">
        <test-method status="FAIL" signature="m1()[pri:0, instance:default1.Screenshot_Of_Failed_Test_Cases@5f150435]" name="m1" duration-ms="11416" started-at="2019-03-23T11:18:48Z" finished-at="2019-03-23T11:19:00Z">
          <exception class="java.lang.AssertionError">
            <message>
              <![CDATA[expected [8] but found [5]]]>
            </message>
            <full-stacktrace>
              <![CDATA[java.lang.AssertionError: expected [8] but found [5]
	at org.testng.Assert.fail(Assert.java:94)
	at org.testng.Assert.failNotEquals(Assert.java:513)
	at org.testng.Assert.assertEqualsImpl(Assert.java:135)
	at org.testng.Assert.assertEquals(Assert.java:116)
	at org.testng.Assert.assertEquals(Assert.java:389)
	at org.testng.Assert.assertEquals(Assert.java:399)
	at default1.Screenshot_Of_Failed_Test_Cases.m1(Screenshot_Of_Failed_Test_Cases.java:30)
	at sun.reflect.NativeMethodAccessorImpl.invoke0(Native Method)
	at sun.reflect.NativeMethodAccessorImpl.invoke(Unknown Source)
	at sun.reflect.DelegatingMethodAccessorImpl.invoke(Unknown Source)
	at java.lang.reflect.Method.invoke(Unknown Source)
	at org.testng.internal.MethodInvocationHelper.invokeMethod(MethodInvocationHelper.java:86)
	at org.testng.internal.Invoker.invokeMethod(Invoker.java:645)
	at org.testng.internal.Invoker.invokeTestMethod(Invoker.java:822)
	at org.testng.internal.Invoker.invokeTestMethods(Invoker.java:1130)
	at org.testng.internal.TestMethodWorker.invokeTestMethods(TestMethodWorker.java:129)
	at org.testng.internal.TestMethodWorker.run(TestMethodWorker.java:112)
	at org.testng.TestRunner.privateRun(TestRunner.java:782)
	at org.testng.TestRunner.run(TestRunner.java:632)
	at org.testng.SuiteRunner.runTest(SuiteRunner.java:366)
	at org.testng.SuiteRunner.runSequentially(SuiteRunner.java:361)
	at org.testng.SuiteRunner.privateRun(SuiteRunner.java:319)
	at org.testng.SuiteRunner.run(SuiteRunner.java:268)
	at org.testng.SuiteRunnerWorker.runSuite(SuiteRunnerWorker.java:52)
	at org.testng.SuiteRunnerWorker.run(SuiteRunnerWorker.java:86)
	at org.testng.TestNG.runSuitesSequentially(TestNG.java:1244)
	at org.testng.TestNG.runSuitesLocally(TestNG.java:1169)
	at org.testng.TestNG.run(TestNG.java:1064)
	at org.testng.remote.RemoteTestNG.run(RemoteTestNG.java:113)
	at org.testng.remote.RemoteTestNG.initAndRun(RemoteTestNG.java:206)
	at org.testng.remote.RemoteTestNG.main(RemoteTestNG.java:177)
]]>
            </full-stacktrace>
          </exception> <!-- java.lang.AssertionError -->
          <reporter-output>
          </reporter-output>
        </test-method> <!-- m1 -->
        <test-method status="PASS" signature="m4(org.testng.ITestResult)[pri:0, instance:default1.Screenshot_Of_Failed_Test_Cases@5f150435]" name="m4" is-config="true" duration-ms="651" started-at="2019-03-23T11:19:00Z" finished-at="2019-03-23T11:19:00Z">
          <params>
            <param index="0">
              <value>
                <![CDATA[[TestResult name=m1 status=FAILURE method=Screenshot_Of_Failed_Test_Cases.m1()[pri:0, instance:default1.Screenshot_Of_Failed_Test_Cases@5f150435] output={null}]]]>
              </value>
            </param>
          </params>
          <reporter-output>
          </reporter-output>
        </test-method> <!-- m4 -->
      </class> <!-- default1.Screenshot_Of_Failed_Test_Cases -->
    </test> <!-- Default test -->
  </suite> <!-- Default suite -->
</testng-results>
